<mujoco>
  <compiler angle="degree" coordinate="local" inertiafromgeom="true"/>
  <option integrator="RK4" timestep="0.003" gravity="0 0 -9.7"/>
  <default>
    <!-- <joint armature="1" damping="1" limited="false"/> -->
    <!-- <geom conaffinity="1" contype="1" condim="1" friction="2 0.005 0.0001" margin="0.001" rgba="0.8 0.6 0.4 1"/> -->
  </default>
  <asset>
    <texture builtin="gradient" height="100" rgb1="1 1 1" rgb2="0 0 0" type="skybox" width="100"/>
    <texture builtin="flat" height="1278" mark="cross" markrgb="1 1 1" name="texgeom" random="0.01" rgb1="0.8 0.6 0.4" rgb2="0.8 0.6 0.4" type="cube" width="127"/>
    <texture builtin="checker" height="100" name="texplane" rgb1="0 0 0" rgb2="0.8 0.8 0.8" type="2d" width="100"/>
    <material name="MatPlane" reflectance="0.5" shininess="1" specular="1" texrepeat="30 30" texture="texplane"/>
    <material name="geom" texture="texgeom" texuniform="true"/>
  </asset>
  <worldbody>
    <light cutoff="100" diffuse="1 1 1" dir="-0 0 -1.3" directional="true" exponent="1" pos="0 0 1.3" specular=".1 .1 .1"/>
    <geom material="MatPlane" name="floor" pos="0 0 0" rgba="0.8 0.9 0.8 1" size="40 40 40" type="plane"/>
    <!-- <body name="camera" pos= "0 0 15">
      <geom name="camerahead" pos="0 0 0" size="0.05" type="sphere"/>
      <camera name="track" mode="trackcom" pos="0 0 0" xyaxes="1 0 0 0 1 0"/> -->
      <!-- <joint axis="1 0 0" name="camerax" pos="0 0 0" type="slide" frictionloss="1"/> -->
      <!-- <joint axis="0 0 1" name="cameray" pos="0 0 0" type="slide" frictionloss="1"/> -->
    <!-- </body> -->
    <body name="torso" pos="0 0 5">
      <joint armature="0" damping="0" limited="false" name="root" pos="0 0 0" stiffness="0" type="free"/>
      <!-- <geom fromto="0 -.07 0 0 .07 0" name="torso1" size="0.07" type="capsule"/> -->
      <!-- <geom name="head" pos="0 0 .19" size=".09" type="sphere" user="258"/> -->
      <!-- <geom fromto="-.01 -.06 -.12 -.01 .06 -.12" name="uwaist" size="0.06" type="capsule"/> -->
      <geom material="MatPlane" name="pointarrow" pos="0 0 0" size="0.5" type="sphere"/>
      <body name="base1" pos="0 0 0">
        <geom material="MatPlane" name="pointbody1" pos="0 0 0" size="0.25" type="sphere"/>
        <joint axis="0 0 1" limited="false" name="rot5" pos="0 0 0" type="hinge"/>
          <joint axis="0 1 0" limited="false" name="rot1" pos="0 0 0" type="hinge"/>
      </body>
<!-- 
      <body name="base1" pos="2 2 -1">
        <geom material="MatPlane" name="pointbody1" pos="0 0 0" size="0.1" type="sphere"/>
        <joint axis="0 0 1" limited="false" name="rot5" pos="0 0 0" type="hinge"/>
          <joint axis="0 1 0" limited="false" name="rot1" pos="0 0 0" type="hinge"/>
      </body>
      <body name="base2" pos="2 -2 -1">
        <geom material="MatPlane" name="pointbody2" pos="0 0 0" size="0.1" type="sphere"/>
        <joint axis="0 1 0" limited="false" name="rot2" pos="0 0 0" type="hinge"/>
      </body>
      <body name="base3" pos="-2 2 -1">
        <geom material="MatPlane" name="pointbody3" pos="0 0 0" size="0.1" type="sphere"/>
        <joint axis="0 1 0" limited="false" name="rot3" pos="0 0 0" type="hinge"/>
      </body>
      <body name="base4" pos="-2 -2 -1">
        <geom material="MatPlane" name="pointbody4" pos="0 0 0" size="0.1" type="sphere"/>
        <joint axis="0 1 0" limited="false" name="rot4" pos="0 0 0" type="hinge"/>
      </body> -->
      <!-- <geom name="pointarrow" pos="0.5 0 0.5" size="0.5 0.1 0.1" type="box"/> -->
      <!-- <joint axis="0 1 0" limited="false" name="rot" pos="0 0 0" type="hinge" frictionloss="1"/> -->
      <!-- <joint axis="1 0 0" name="ballx" pos="0 0 0" type="slide" frictionloss="1"/> -->
      <!-- <joint axis="0 1 0" name="bally" pos="0 0 0" type="slide" frictionloss="1"/> -->
    </body>
  </worldbody>
  <actuator>
    <!-- Those are just dummy actuators for providing ranges -->
    <!-- <motor ctrllimited="true" ctrlrange="-50 50" joint="ballx"/> -->
    <motor ctrllimited="true" ctrlrange="-25 25" joint="rot1"/>
    <!-- <motor ctrllimited="true" ctrlrange="-250 250" joint="rot2"/> -->
    <!-- <motor ctrllimited="true" ctrlrange="-250 250" joint="rot3"/> -->
    <!-- <motor ctrllimited="true" ctrlrange="-250 250" joint="rot4"/> -->
    <!-- <velocity name="l" joint="rot4" kv="100"/> -->
    <!-- <motor ctrllimited="true" ctrlrange="-50 50" joint="bally"/> -->
    <!-- <motor ctrllimited="true" ctrlrange="-1 1" joint="cameray"/> -->
  </actuator>
</mujoco>
