<mujoco>
  <compiler angle="degree" coordinate="local" inertiafromgeom="true"/>
  <option integrator="RK4" timestep="0.03" gravity="0 0 0"/>
  <default>
    <!-- <joint armature="1" damping="1" limited="false"/> -->
    <!-- <geom conaffinity="1" contype="1" condim="1" friction="2 0.005 0.0001" margin="0.001" rgba="0.8 0.6 0.4 1"/> -->
  </default>
  <asset>
    <texture builtin="gradient" height="100" rgb1="1 1 1" rgb2="0 0 0" type="skybox" width="100"/>
    <texture builtin="flat" height="1278" mark="cross" markrgb="1 1 1" name="texgeom" random="0.01" rgb1="0.8 0.6 0.4" rgb2="0.8 0.6 0.4" type="cube" width="127"/>
    <texture builtin="checker" height="100" name="texplane" rgb1="0 0 0" rgb2="0.8 0.8 0.8" type="2d" width="100"/>
    <material name="MatPlane" reflectance="0.5" shininess="1" specular="1" texrepeat="30 30" texture="texplane"/>
    <material name="geom" texture="texgeom" texuniform="true"/>
  </asset>
  <worldbody>
    <light cutoff="100" diffuse="1 1 1" dir="-0 0 -1.3" directional="true" exponent="1" pos="0 0 1.3" specular=".1 .1 .1"/>
    <geom material="geom" name="floor" pos="0 0 0" rgba="0.8 0.9 0.8 1" size="40 40 40" type="plane"/>
    <body name="camera" pos= "0 0 15">
      <geom name="camerahead" pos="0 0 0" size="0.05" type="sphere"/>
      <camera name="track" mode="trackcom" pos="0 0 0" xyaxes="1 0 0 0 1 0"/> 
    </body>
    <body name="torso" pos="0 0 0.1">
      <geom material="MatPlane" name="visibleObject" pos="0 0 0" size="5 2 0.001" type="box"/>
      <joint axis="1 0 0" limited="false" name="x" pos="0 0 0" type="slide"/>
      <joint axis="0 1 0" limited="false" name="y" pos="0 0 0" type="slide"/>
        <joint axis="0 0 1" limited="false" name="rot" pos="0 0 0" type="hinge"/>
      <!-- <body name="movementBody" pos="0 0 0"> -->
        <!-- <geom material="MatPlane" name="movementObject" pos="0 0 0" size="0.1" type="sphere"/> -->
        <!-- <joint axis="0 0 1" limited="false" name="rot" pos="0 0 0" type="hinge"/> -->
      <!-- </body> -->
    </body>
  </worldbody>
  <actuator>
    <!-- Those are just dummy actuators for providing ranges -->
    <motor ctrllimited="true" ctrlrange="-1 1" joint="x"/>
    <motor ctrllimited="true" ctrlrange="-5 5" joint="rot"/>
    <motor ctrllimited="true" ctrlrange="-1 1" joint="y"/>
  </actuator>
</mujoco>
